Workbook

Sheet IGSDB_110
A1: ID | B1: Name | C1: Source | D1: SpectralData | E1: AngularFunction | F1: Thickness | G1: Tsol | H1: Rsol1 | I1: Rsol2 | J1: Tvis | K1: Rvis1 | L1: Rvis2 | M1: Tir | N1: emis1 | O1: emis2 | P1: Conductivity | Q1: Comment | R1: Manufacturer | S1: ProductName | T1: Color | U1: Certification | V1: Status | W1: Timestamp | X1: Specularity | Y1: Tvis2 | Z1: Tsol2 | AA1: MaterialID
A2: 28502 | B2: 0.76SR Interlayer.ASG | C2: IGDB v81.0 | D2: 1 | E2: 0 | F2: 6.56 | G2: 0.383793 | H2: 0.054954 | I2: 0.054954 | J2: 0.749578 | K2: 0.073112 | L2: 0.073112 | M2: 0 | N2: 0.84 | O2: 0.84 | P2: 0.705 | R2: ASG Architectural Solutions Glass Pty Ltd | S2: 0.76SR Interlayer | T2: 14738646 | V2: 256 | W2: 1675888761 | X2: 0 | Y2: 0.749578 | Z2: 0.383793 | AA2: 0
A3: 21515 | B3: 007_PET_BUT.KUR | C3: IGDB v66.0 | D3: 1 | E3: 0 | F3: 0.18 | G3: 0.861647 | H3: 0.117173 | I3: 0.117279 | J3: 0.86924 | K3: 0.1222 | L3: 0.122131 | M3: 0 | N3: 0.95 | O3: 0.95 | P3: 0.155 | R3: Kuraray | S3: BE-1028 PET Film | T3: 15528176 | U3: # | V3: 256 | W3: 1586299407 | X3: 0 | Y3: 0.86924 | Z3: 0.861647 | AA3: 0
A4: 8200 | B4: 01_Clear_10.syp | C4: IGDB v15.4 | D4: 1 | E4: 0 | F4: 10 | G4: 0.746867 | H4: 0.070326 | I4: 0.070326 | J4: 0.87757 | K4: 0.080491 | L4: 0.080491 | M4: 0 | N4: 0.84 | O4: 0.84 | P4: 1 | R4: SYP GLASS GROUP CO.,LTD | S4: Clear Float Glass | T4: 15659756 | V4: 256 | W4: 1510862477 | X4: 0 | Y4: 0.87757 | Z4: 0.746867 | AA4: 0
A5: 8201 | B5: 01_Clear_12.syp | C5: IGDB v15.4 | D5: 1 | E5: 0 | F5: 12 | G5: 0.722631 | H5: 0.067336 | I5: 0.067336 | J5: 0.86955 | K5: 0.078733 | L5: 0.078733 | M5: 0 | N5: 0.84 | O5: 0.84 | P5: 1 | R5: SYP GLASS GROUP CO.,LTD | S5: Clear Float Glass | T5: 15594219 | V5: 256 | W5: 1510862477 | X5: 0 | Y5: 0.86955 | Z5: 0.722631 | AA5: 0
A6: 8202 | B6: 01_Clear_15.syp | C6: IGDB v15.4 | D6: 1 | E6: 0 | F6: 15 | G6: 0.687364 | H6: 0.069649 | I6: 0.069649 | J6: 0.851845 | K6: 0.082041 | L6: 0.082041 | M6: 0 | N6: 0.84 | O6: 0.84 | P6: 1 | R6: SYP GLASS GROUP CO.,LTD | S6: Clear Float Glass | T6: 15462632 | V6: 256 | W6: 1510862477 | X6: 0 | Y6: 0.851845 | Z6: 0.687364 | AA6: 0
A7: 8207 | B7: 01_Clear_19.syp | C7: IGDB v58.0 | D7: 1 | E7: 0 | F7: 19 | G7: 0.613264 | H7: 0.061559 | I7: 0.061559 | J7: 0.833598 | K7: 0.074965 | L7: 0.074965 | M7: 0 | N7: 0.84 | O7: 0.84 | P7: 1 | R7: SYP GLASS GROUP CO.,LTD | S7: Clear Float Glass | T7: 15331043 | U7: # | V7: 256 | W7: 1513283368 | X7: 0 | Y7: 0.833598 | Z7: 0.613264 | AA7: 0
A8: 8203 | B8: 01_Clear_4.syp | C8: IGDB v15.4 | D8: 1 | E8: 0 | F8: 4 | G8: 0.847464 | H8: 0.077616 | I8: 0.077616 | J8: 0.901963 | K8: 0.080769 | L8: 0.080769 | M8: 0 | N8: 0.84 | O8: 0.84 | P8: 1 | R8: SYP GLASS GROUP CO.,LTD | S8: Clear Float Glass | T8: 15856882 | U8: # | V8: 256 | W8: 1510862477 | X8: 0 | Y8: 0.901963 | Z8: 0.847464 | AA8: 0
A9: 8204 | B9: 01_Clear_5.syp | C9: IGDB v15.4 | D9: 1 | E9: 0 | F9: 5 | G9: 0.831186 | H9: 0.076506 | I9: 0.076506 | J9: 0.897546 | K9: 0.080724 | L9: 0.080724 | M9: 0 | N9: 0.84 | O9: 0.84 | P9: 1 | R9: SYP GLASS GROUP CO.,LTD | S9: Clear Float Glass | T9: 15856881 | U9: # | V9: 256 | W9: 1510862477 | X9: 0 | Y9: 0.897546 | Z9: 0.831186 | AA9: 0
A10: 8205 | B10: 01_Clear_6.syp | C10: IGDB v17.4 | D10: 1 | E10: 0 | F10: 6 | G10: 0.803698 | H10: 0.07383 | I10: 0.07383 | J10: 0.892204 | K10: 0.081512 | L10: 0.081512 | M10: 0 | N10: 0.84 | O10: 0.84 | P10: 1 | R10: SYP GLASS GROUP CO.,LTD | S10: Clear Float Glass | T10: 15791344 | U10: # | V10: 256 | W10: 1510862499 | X10: 0 | Y10: 0.892204 | Z10: 0.803698 | AA10: 0
A11: 8206 | B11: 01_Clear_8.syp | C11: IGDB v15.4 | D11: 1 | E11: 0 | F11: 8 | G11: 0.771074 | H11: 0.071177 | I11: 0.071177 | J11: 0.884304 | K11: 0.080521 | L11: 0.080521 | M11: 0 | N11: 0.84 | O11: 0.84 | P11: 1 | R11: SYP GLASS GROUP CO.,LTD | S11: Clear Float Glass | T11: 15725550 | V11: 256 | W11: 1510862478 | X11: 0 | Y11: 0.884304 | Z11: 0.771074 | AA11: 0
A12: 21529 | B12: 015_Asahi_Grey.KUR | C12: IGDB v67.0 | D12: 1 | E12: 0 | F12: 4.601 | G12: 0.501444 | H12: 0.059784 | I12: 0.059784 | J12: 0.390934 | K12: 0.057923 | L12: 0.057923 | M12: 0 | N12: 0.837 | O12: 0.837 | P12: 0.774 | R12: Kuraray | S12: Trosifol Asahi Grey | T12: 11250590 | U12: # | V12: 256 | W12: 1586299409 | X12: 0 | Y12: 0.390934 | Z12: 0.501444 | AA12: 0
A13: 10528 | B13: 015_BG_R15_CLEAR.TRO | C13: IGDB v29.0 | D13: 1 | E13: 0 | F13: 4.5455 | G13: 0.811855 | H13: 0.076009 | I13: 0.074697 | J13: 0.898235 | K13: 0.081446 | L13: 0.080586 | M13: 0 | N13: 0.84 | O13: 0.84 | P13: 0.7839 | R13: TROSIFOL | S13: Trosifol 015 clear BG R15 PVB LAMINATE | T13: 15856882 | U13: # | V13: 256 | W13: 1510863347 | X13: 0 | Y13: 0.898235 | Z13: 0.811855 | AA13: 0
A14: 21517 | B14: 015_Clear_B100.KUR | C14: IGDB v67.0 | D14: 1 | E14: 0 | F14: 4.562 | G14: 0.82661 | H14: 0.078486 | I14: 0.078486 | J14: 0.901661 | K14: 0.085975 | L14: 0.085975 | M14: 0 | N14: 0.837 | O14: 0.837 | P14: 0.792 | R14: Kuraray | S14: Trosifol Clear | T14: 15791347 | U14: # | V14: 256 | W14: 1586299407 | X14: 0 | Y14: 0.901661 | Z14: 0.82661 | AA14: 0
A15: 21501 | B15: 015_Clear_B500.KUR | C15: IGDB v67.0 | D15: 1 | E15: 0 | F15: 4.553 | G15: 0.830012 | H15: 0.07768 | I15: 0.07768 | J15: 0.900996 | K15: 0.085292 | L15: 0.085292 | M15: 0 | N15: 0.837 | O15: 0.837 | P15: 0.796 | R15: Kuraray | S15: Trosifol Clear | T15: 15856883 | U15: # | V15: 256 | W15: 1586299407 | X15: 0 | Y15: 0.900996 | Z15: 0.830012 | AA15: 0
A16: 21530 | B16: 015_Grey.KUR | C16: IGDB v67.0 | D16: 1 | E16: 0 | F16: 4.579 | G16: 0.550901 | H16: 0.062252 | I16: 0.062252 | J16: 0.427532 | K16: 0.059826 | L16: 0.059826 | M16: 0 | N16: 0.837 | O16: 0.837 | P16: 0.784 | R16: Kuraray | S16: Trosifol Grey | T16: 12169641 | U16: # | V16: 256 | W16: 1586299409 | X16: 0 | Y16: 0.427532 | Z16: 0.550901 | AA16: 0
A17: 21545 | B17: 015_Light_BlueGreen.KUR | C17: IGDB v67.0 | D17: 1 | E17: 0 | F17: 4.581 | G17: 0.720985 | H17: 0.071879 | I17: 0.071879 | J17: 0.722466 | K17: 0.074119 | L17: 0.074119 | M17: 0 | N17: 0.837 | O17: 0.837 | P17: 0.783 | R17: Kuraray | S17: Trosifol Light Blue-Green | T17: 14672587 | U17: # | V17: 256 | W17: 1586299523 | X17: 0 | Y17: 0.722466 | Z17: 0.720985 | AA17: 0
A18: 21532 | B18: 015_Light_Brown.KUR | C18: IGDB v67.0 | D18: 1 | E18: 0 | F18: 4.549 | G18: 0.577896 | H18: 0.061987 | I18: 0.061987 | J18: 0.549099 | K18: 0.062445 | L18: 0.062445 | M18: 0 | N18: 0.837 | O18: 0.837 | P18: 0.798 | R18: Kuraray | S18: Trosifol Light Brown | T18: 11846346 | U18: # | V18: 256 | W18: 1586299409 | X18: 0 | Y18: 0.549099 | Z18: 0.577896 | AA18: 0
A19: 10531 | B19: 015_LIGHT_BROWN_BG_R15.TRO | C19: IGDB v29.0 | D19: 1 | E19: 0 | F19: 4.577 | G19: 0.567102 | H19: 0.069156 | I19: 0.066417 | J19: 0.552438 | K19: 0.070781 | L19: 0.067987 | M19: 0 | N19: 0.84 | O19: 0.84 | P19: 0.7694 | R19: TROSIFOL | S19: Trosifol 015 light brown BG R15 PVB LAMINATE | T19: 11912138 | U19: # | V19: 256 | W19: 1510863347 | X19: 0 | Y19: 0.552438 | Z19: 0.567102 | AA19: 0
A20: 21528 | B20: 015_Light_Green.KUR | C20: IGDB v67.0 | D20: 1 | E20: 0 | F20: 4.529 | G20: 0.765258 | H20: 0.074956 | I20: 0.074956 | J20: 0.826927 | K20: 0.080714 | L20: 0.080714 | M20: 0 | N20: 0.837 | O20: 0.837 | P20: 0.808 | R20: Kuraray | S20: Trosifol Light Green | T20: 15200724 | U20: # | V20: 256 | W20: 1586299409 | X20: 0 | Y20: 0.826927 | Z20: 0.765258 | AA20: 0
A21: 21538 | B21: 015_Medium_Blue.KUR | C21: IGDB v67.0 | D21: 1 | E21: 0 | F21: 4.532 | G21: 0.572926 | H21: 0.073866 | I21: 0.073866 | J21: 0.361383 | K21: 0.06263 | L21: 0.06263 | M21: 0 | N21: 0.837 | O21: 0.837 | P21: 0.807 | R21: Kuraray | S21: Trosifol Medium Blue | T21: 15318528 | U21: # | V21: 256 | W21: 1586299410 | X21: 0 | Y21: 0.361383 | Z21: 0.572926 | AA21: 0
A22: 21535 | B22: 015_Medium_Bronze.KUR | C22: IGDB v67.0 | D22: 1 | E22: 0 | F22: 4.525 | G22: 0.599022 | H22: 0.063475 | I22: 0.063475 | J22: 0.558685 | K22: 0.064267 | L22: 0.064267 | M22: 0 | N22: 0.837 | O22: 0.837 | P22: 0.81 | R22: Kuraray | S22: Trosifol Medium Bronze | T22: 12305103 | U22: # | V22: 256 | W22: 1586299410 | X22: 0 | Y22: 0.558685 | Z22: 0.599022 | AA22: 0
A23: 21533 | B23: 015_Medium_Brown.KUR | C23: IGDB v67.0 | D23: 1 | E23: 0 | F23: 4.551 | G23: 0.317659 | H23: 0.051492 | I23: 0.051492 | J23: 0.226271 | K23: 0.051028 | L23: 0.051028 | M23: 0 | N23: 0.837 | O23: 0.837 | P23: 0.797 | R23: Kuraray | S23: Trosifol Medium Brown | T23: 6913936 | U23: # | V23: 256 | W23: 1586299409 | X23: 0 | Y23: 0.226271 | Z23: 0.317659 | AA23: 0
... A48: 21510 | B48: 035_SentryGlas.KUR | C48: IGDB v67.0 | D48: 1 | E48: 0 | F48: 5.155 | G48: 0.803539 | H48: 0.075548 | I48: 0.075548 | J48: 0.899968 | K48: 0.08477 | L48: 0.08477 | M48: 0 | N48: 0.837 | O48: 0.837 | P48: 0.602 | R48: Kuraray | S48: SentryGlas | T48: 15791346 | U48: # | V48: 256 | W48: 1586299407 | X48: 0 | Y48: 0.899968 | Z48: 0.803539 | AA48: 0
A49: 29050 | B49: 038_PFAT_3Clr.CCP | C49: IGDB v98.0 | D49: 1 | E49: 0 | F49: 5.99 | G49: 0.766487 | H49: 0.069516 | I49: 0.069516 | J49: 0.882598 | K49: 0.07864 | L49: 0.07864 | M49: 0 | N49: 0.84 | O49: 0.84 | P49: 0.819 | R49: Chang Chun Petrochemical Co.,Ltd. | S49: WINLITE_Polyvinyl Butyral Film_PFAT | T49: 15659759 | V49: 256 | W49: 1739489646 | X49: 0 | Y49: 0.882598 | Z49: 0.766487 | AA49: 0
A50: 1800 | B50: 038_Saflex_Clear_3Clr.EMN | C50: IGDB v66.0 | D50: 1 | E50: 0 | F50: 6.3 | G50: 0.768757 | H50: 0.0709 | I50: 0.071084 | J50: 0.893768 | K50: 0.083316 | L50: 0.083563 | M50: 0 | N50: 0.84 | O50: 0.84 | P50: 0.788 | R50: Eastman Chemical Company | S50: Saflex® Clear - RA|RB | T50: 15856879 | U50: # | V50: 256 | W50: 1586299363 | X50: 0 | Y50: 0.893768 | Z50: 0.768757 | AA50: 0
A51: 1901 | B51: 038_Vanceva_0001_3Clr.EMN | C51: IGDB v66.0 | D51: 1 | E51: 0 | F51: 6.3 | G51: 0.736342 | H51: 0.071931 | I51: 0.07195 | J51: 0.777745 | K51: 0.076955 | L51: 0.077061 | M51: 0 | N51: 0.84 | O51: 0.84 | P51: 0.788 | R51: Eastman Chemical Company | S51: Vanceva® Coral Rose - VCV 0001 | T51: 15261175 | U51: # | V51: 256 | W51: 1586299369 | X51: 0 | Y51: 0.777745 | Z51: 0.736342 | AA51: 0
A52: 1902 | B52: 038_Vanceva_0002_3Clr.EMN | C52: IGDB v66.0 | D52: 1 | E52: 0 | F52: 6.3 | G52: 0.710006 | H52: 0.069923 | I52: 0.06976 | J52: 0.782775 | K52: 0.075819 | L52: 0.075788 | M52: 0 | N52: 0.84 | O52: 0.84 | P52: 0.788 | R52: Eastman Chemical Company | S52: Vanceva® Aquamarine - VCV 0002 | T52: 15920583 | U52: # | V52: 256 | W52: 1586299369 | X52: 0 | Y52: 0.782775 | Z52: 0.710006 | AA52: 0
A53: 1903 | B53: 038_Vanceva_0003_3Clr.EMN | C53: IGDB v66.0 | D53: 1 | E53: 0 | F53: 6.3 | G53: 0.691364 | H53: 0.068621 | I53: 0.068641 | J53: 0.778548 | K53: 0.075795 | L53: 0.075792 | M53: 0 | N53: 0.84 | O53: 0.84 | P53: 0.788 | R53: Eastman Chemical Company | S53: Vanceva® Smoke Grey - VCV 0003 | T53: 14673379 | U53: # | V53: 256 | W53: 1586299369 | X53: 0 | Y53: 0.778548 | Z53: 0.691364 | AA53: 0
A54: 1904 | B54: 038_Vanceva_0004_3Clr.EMN | C54: IGDB v66.0 | D54: 1 | E54: 0 | F54: 6.3 | G54: 0.670126 | H54: 0.074838 | I54: 0.075177 | J54: 0.822698 | K54: 0.095872 | L54: 0.09616 | M54: 0 | N54: 0.84 | O54: 0.84 | P54: 0.788 | R54: Eastman Chemical Company | S54: Vanceva® Sahara Sun - VCV 0004 | T54: 1961457 | U54: # | V54: 256 | W54: 1586299369 | X54: 0 | Y54: 0.822698 | Z54: 0.670126 | AA54: 0
A55: 1905 | B55: 038_Vanceva_0005_3Clr.EMN | C55: IGDB v66.0 | D55: 1 | E55: 0 | F55: 6.3 | G55: 0.658613 | H55: 0.068812 | I55: 0.06896 | J55: 0.503076 | K55: 0.066394 | L55: 0.066342 | M55: 0 | N55: 0.84 | O55: 0.84 | P55: 0.788 | R55: Eastman Chemical Company | S55: Vanceva® Ruby Red - VCV 0005 | T55: 13212159 | U55: # | V55: 256 | W55: 1586299370 | X55: 0 | Y55: 0.503076 | Z55: 0.658613 | AA55: 0
A56: 1906 | B56: 038_Vanceva_0006_3Clr.EMN | C56: IGDB v66.0 | D56: 1 | E56: 0 | F56: 6.3 | G56: 0.581735 | H56: 0.066743 | I56: 0.066925 | J56: 0.515691 | K56: 0.064739 | L56: 0.064775 | M56: 0 | N56: 0.84 | O56: 0.84 | P56: 0.788 | R56: Eastman Chemical Company | S56: Vanceva® Sapphire - VCV 0006 | T56: 15848960 | U56: # | V56: 256 | W56: 1586299370 | X56: 0 | Y56: 0.515691 | Z56: 0.581735 | AA56: 0
A57: 1907 | B57: 038_Vanceva_0007_3Clr.EMN | C57: IGDB v66.0 | D57: 1 | E57: 0 | F57: 6.3 | G57: 0.510861 | H57: 0.058269 | I57: 0.058177 | J57: 0.517839 | K57: 0.060489 | L57: 0.060159 | M57: 0 | N57: 0.84 | O57: 0.84 | P57: 0.788 | R57: Eastman Chemical Company | S57: Vanceva® Evening Shadow - VCV 0007 | T57: 11583171 | U57: # | V57: 256 | W57: 1586299370 | X57: 0 | Y57: 0.517839 | Z57: 0.510861 | AA57: 0
A58: 1908 | B58: 038_Vanceva_0008_3Clr.EMN | C58: IGDB v66.0 | D58: 1 | E58: 0 | F58: 6.32 | G58: 0.712137 | H58: 0.059356 | I58: 0.059286 | J58: 0.854367 | K58: 0.066152 | L58: 0.066047 | M58: 0 | N58: 0.84 | O58: 0.84 | P58: 0.789 | R58: Eastman Chemical Company | S58: Vanceva® Golden Light - VCV 0008 | T58: 10940911 | U58: # | V58: 256 | W58: 1586299370 | X58: 0 | Y58: 0.854367 | Z58: 0.712137 | AA58: 0
A59: 1909 | B59: 038_Vanceva_0009_3Clr.EMN | C59: IGDB v66.0 | D59: 1 | E59: 0 | F59: 6.3 | G59: 0.597939 | H59: 0.06731 | I59: 0.06731 | J59: 0.68103 | K59: 0.072282 | L59: 0.072282 | M59: 0 | N59: 0.84 | O59: 0.84 | P59: 0.788 | R59: Eastman Chemical Company | S59: Vanceva® Arctic Snow - VCV 0009 | T59: 13621463 | U59: # | V59: 256 | W59: 1586299370 | X59: 0 | Y59: 0.68103 | Z59: 0.597939 | AA59: 0
A60: 1910 | B60: 038_Vanceva_000A_3Clr.EMN | C60: IGDB v66.0 | D60: 1 | E60: 0 | F60: 6.3 | G60: 0.672659 | H60: 0.072677 | I60: 0.072677 | J60: 0.81395 | K60: 0.082727 | L60: 0.082727 | M60: 0 | N60: 0.84 | O60: 0.84 | P60: 0.788 | R60: Eastman Chemical Company | S60: Vanceva® Cool White - VCV 000A | T60: 14936806 | U60: # | V60: 256 | W60: 1586299370 | X60: 0 | Y60: 0.81395 | Z60: 0.672659 | AA60: 0
A61: 1911 | B61: 038_Vanceva_000C_3Clr.EMN | C61: IGDB v66.0 | D61: 1 | E61: 0 | F61: 6.3 | G61: 0.396468 | H61: 0.058311 | I61: 0.058415 | J61: 0.166266 | K61: 0.056887 | L61: 0.057063 | M61: 0 | N61: 0.84 | O61: 0.84 | P61: 0.788 | R61: Eastman Chemical Company | S61: Vanceva® Deep Red - VCV 000C | T61: 5781193 | U61: # | V61: 256 | W61: 1586299371 | X61: 0 | Y61: 0.166266 | Z61: 0.396468 | AA61: 0
... A76: 1890 | B76: 038_Vanceva_S-7558_3Clr.EMN | C76: IGDB v66.0 | D76: 1 | E76: 0 | F76: 6.3 | G76: 0.617238 | H76: 0.065691 | I76: 0.065664 | J76: 0.594111 | K76: 0.065998 | L76: 0.065921 | M76: 0 | N76: 0.84 | O76: 0.84 | P76: 0.788 | R76: Eastman Chemical Company | S76: Vanceva® Sky Earth Tone - RB S-7558 | T76: 14733493 | U76: # | V76: 256 | W76: 1586299368 | X76: 0 | Y76: 0.594111 | Z76: 0.617238 | AA76: 0
A77: 8211 | B77: 04_Bronze_10.syp | C77: IGDB v15.4 | D77: 1 | E77: 0 | F77: 10 | G77: 0.302965 | H77: 0.047316 | I77: 0.047316 | J77: 0.33077 | K77: 0.047989 | L77: 0.047989 | M77: 0 | N77: 0.84 | O77: 0.84 | P77: 1 | R77: SYP GLASS GROUP CO.,LTD | S77: 04-Bronze Float Glass | T77: 8951723 | V77: 256 | W77: 1510862478 | X77: 0 | Y77: 0.33077 | Z77: 0.302965 | AA77: 0
A78: 8212 | B78: 04_Bronze_12.syp | C78: IGDB v15.4 | D78: 1 | E78: 0 | F78: 12 | G78: 0.238652 | H78: 0.04564 | I78: 0.04564 | J78: 0.268993 | K78: 0.046291 | L78: 0.046291 | M78: 0 | N78: 0.84 | O78: 0.84 | P78: 1 | R78: SYP GLASS GROUP CO.,LTD | S78: 04-Bronze Float Glass | T78: 7899549 | V78: 256 | W78: 1510862479 | X78: 0 | Y78: 0.268993 | Z78: 0.238652 | AA78: 0
...

Sheet IGSDB Product Availability
B1: IGSDB Coated Glass Availability Matrix (NFRC ID)
B2: Manufacturer | C2: Product Name | D2: 4mm | E2: 5mm | F2: 6mm | G2: Notes
B3: Cardinal | C3: C180 | D3: 2192 | E3: 2193 | F3: 2194
B4: Cardinal | C4: C270 | D4: 2027 | E4: 2028 | F4: 2029
B5: Cardinal | C5: C272 | D5: 2012 | E5: 2013 | F5: 2014
B6: Cardinal | C6: C340 | D6: 2165 | E6: 2166 | F6: 2167
B7: Cardinal | C7: C366 | D7: 2155 | E7: 2156 | F7: 2157
B8: Cardinal | C8: C452 | D8: 2105 | E8: 2106 | F8: 2107
B9: Vitro | C9: SB60 Clear | D9: 5282 | E9: 5283 | F9: 5284
B10: Vitro | C10: SB70 Clear | D10: 5433 | E10: 5434 | F10: 5439
B11: Vitro | C11: SB67 | E11: 5475 | F11: 5476 | G11: 5 & 6mm only
B12: Saint-Gobain | C12: ECLAZ II | D12: 20754 | E12: 20755 | F12: 20756 | G12: II = to-be-tempered; annealed also exists. Commercial name: ECLAZ Lumi. Formerly just "ECLAZ"; renamed as part of the ECLAZ range (Lumi/Zen/Sun) launched Oct 2023.
A13: New Add | B13: Saint-Gobain | C13: ECLAZ ONE II | D13: 20762 | E13: 20763 | F13: 20764 | G13: II = to-be-tempered; annealed ECLAZ ONE also exists. Commercial name: ECLAZ Zen (replaced ECLAZ ONE, Oct 2023). Part of ECLAZ range (Lumi/Zen/Sun).
B14: Saint-Gobain | C14: SKN 183 II | F14: 20896 | G14: II = to-be-tempered; annealed SKN 183 also in IGSDB (ID 20892); 6mm only
B15: Saint-Gobain | C15: XTREME 61-29 II | D15: 20979 | F15: 20980 | G15: II = to-be-tempered; annealed XTREME 61-29 also in IGSDB; 4 & 6mm only
B16: Vitro | C16: SB60 Solexia | F16: 5254 | G16: 6mm only
B17: Vitro | C17: SB60 Solarbronze | E17: 5273 | F17: 5274 | G17: 5 & 6mm
B18: Vitro | C18: SB60 Solargray | D18: 5287 | E18: 5288 | F18: 5289
B19: Vitro | C19: SB60 Optigray | F19: 5265 | G19: 6mm only
B20: Vitro | C20: SB60 Solarblue | F20: 5364 | G20: 6mm only
B21: Vitro | C21: SB60 Optiblue | E21: 5423 | F21: 5424 | G21: 5 & 6mm
B22: Vitro | C22: SB70 Solexia | F22: 5393 | G22: 6mm only
B23: Vitro | C23: SB70 Solarbronze | F23: 5377 | G23: 6mm only
B24: Vitro | C24: SB70 Solargray | E24: 5372 | F24: 5373 | G24: No 4mm
B25: Vitro | C25: SB70 Optigray | F25: 5390 | G25: 6mm only
B26: Vitro | C26: SB70 Solarblue | F26: 5396 | G26: 6mm only
B27: Vitro | C27: SB70 Optiblue | E27: 5427 | F27: 5428 | G27: No 4mm
A28: New Add | B28: Vitro | C28: SB60 Starphire | E28: 5348 | F28: 5349 | G28: IGSDB name: Solarban® 60 on Starphire®. No 4mm; 5mm (4.67mm actual), 6mm (5.66mm actual). Also available: 3mm (ID 5346), 8mm (ID 5251), 10mm (ID 5252).
A29: New Add | B29: Vitro | C29: SB72 Starphire | F29: 5435 | G29: IGSDB name: Solarban® 72 on Starphire®. Maps to "SB70" on Starphire in product configs. 6mm only (5.66mm actual). Also available: 8mm (ID 5436), 10mm (ID 5437). No 4mm or 5mm.
B30: Cardinal | C30: Clear Float Glass | D30: 2002 | E30: 2003 | F30: 2004
B31: Vitro | C31: Clear Float Glass | D31: 413 | E31: 414 | F31: 415
B32: Saint-Gobain | C32: SGG PLANICLEAR | D32: 21011 | E32: 21012 | F32: 21013
B33: Vitro | C33: Starphire | D33: 5002 | E33: 5003 | F33: 5004 | G33: Low-iron clear; pair with Starphire-substrate coatings (SB60/SB72 Starphire). Also: 3mm=5001, 8mm=5005.

Sheet Enthermal Configs
A1: Enthermal — Double Pane (Low-E on Surface 2) — IGSDB Verified
A3: Package 1 — Clear Substrate Coatings
A4: # | B4: Coating (Surface 2) | C4: IGSDB Thicknesses | D4: Available Combos (outer/inner mm) | E4: Configs | F4: Notes | G4: Clear lite (inner)
A5: 1 | B5: C180 | C5: 4, 5, 6 | D5: 4/4, 5/4, 5/5, 6/4, 6/5, 6/6 | E5: 6 | G5: =IF(ISNUMBER(SEARCH("Starphire",B5)),"Inner clear — Vitro Starphire (low-iron match)","Inner clear, same mfr as coating") -> Inner clear, same mfr as coating
A6: 2 | B6: C270 | C6: 4, 5, 6 | D6: 4/4, 5/4, 5/5, 6/4, 6/5, 6/6 | E6: 6 | G6: =IF(ISNUMBER(SEARCH("Starphire",B6)),"Inner clear — Vitro Starphire (low-iron match)","Inner clear, same mfr as coating") -> Inner clear, same mfr as coating
A7: 3 | B7: C272 | C7: 4, 5, 6 | D7: 4/4, 5/4, 5/5, 6/4, 6/5, 6/6 | E7: 6 | G7: =IF(ISNUMBER(SEARCH("Starphire",B7)),"Inner clear — Vitro Starphire (low-iron match)","Inner clear, same mfr as coating") -> Inner clear, same mfr as coating
A8: 4 | B8: C340 | C8: 4, 5, 6 | D8: 4/4, 5/4, 5/5, 6/4, 6/5, 6/6 | E8: 6 | G8: =IF(ISNUMBER(SEARCH("Starphire",B8)),"Inner clear — Vitro Starphire (low-iron match)","Inner clear, same mfr as coating") -> Inner clear, same mfr as coating
A9: 5 | B9: C366 | C9: 4, 5, 6 | D9: 4/4, 5/4, 5/5, 6/4, 6/5, 6/6 | E9: 6 | G9: =IF(ISNUMBER(SEARCH("Starphire",B9)),"Inner clear — Vitro Starphire (low-iron match)","Inner clear, same mfr as coating") -> Inner clear, same mfr as coating
A10: 6 | B10: C452 | C10: 4, 5, 6 | D10: 4/4, 5/4, 5/5, 6/4, 6/5, 6/6 | E10: 6 | G10: =IF(ISNUMBER(SEARCH("Starphire",B10)),"Inner clear — Vitro Starphire (low-iron match)","Inner clear, same mfr as coating") -> Inner clear, same mfr as coating
A11: 7 | B11: SB60 Clear | C11: 4, 5, 6 | D11: 4/4, 5/4, 5/5, 6/4, 6/5, 6/6 | E11: 6 | G11: =IF(ISNUMBER(SEARCH("Starphire",B11)),"Inner clear — Vitro Starphire (low-iron match)","Inner clear, same mfr as coating") -> Inner clear, same mfr as coating
A12: 8 | B12: SB70 Clear | C12: 4, 5, 6 | D12: 4/4, 5/4, 5/5, 6/4, 6/5, 6/6 | E12: 6 | G12: =IF(ISNUMBER(SEARCH("Starphire",B12)),"Inner clear — Vitro Starphire (low-iron match)","Inner clear, same mfr as coating") -> Inner clear, same mfr as coating
A13: 9 | B13: SB67 | C13: 5, 6 | D13: 5/4, 5/5, 6/4, 6/5, 6/6 | E13: 5 | F13: No 4mm in IGSDB | G13: =IF(ISNUMBER(SEARCH("Starphire",B13)),"Inner clear — Vitro Starphire (low-iron match)","Inner clear, same mfr as coating") -> Inner clear, same mfr as coating
A14: 10 | B14: SB60 Starphire | C14: 5, 6 | D14: 5/4, 5/5, 6/4, 6/5, 6/6 | E14: 5 | F14: No 4mm in IGSDB; maps to SB60 on Starphire substrate | G14: =IF(ISNUMBER(SEARCH("Starphire",B14)),"Inner clear — Vitro Starphire (low-iron match)","Inner clear, same mfr as coating") -> Inner clear — Vitro Starphire (low-iron match)
A15: 11 | B15: SB72 Starphire | C15: 6 | D15: 6/4, 6/5, 6/6 | E15: 3 | F15: 6mm only in IGSDB; maps to SB70 on Starphire substrate | G15: =IF(ISNUMBER(SEARCH("Starphire",B15)),"Inner clear — Vitro Starphire (low-iron match)","Inner clear, same mfr as coating") -> Inner clear — Vitro Starphire (low-iron match)
A16: 12 | B16: ECLAZ II | C16: 4, 5, 6 | D16: 4/4, 5/4, 5/5, 6/4, 6/5, 6/6 | E16: 6 | F16: Using II (to-be-tempered); Commercial name: ECLAZ Lumi | G16: =IF(ISNUMBER(SEARCH("Starphire",B16)),"Inner clear — Vitro Starphire (low-iron match)","Inner clear, same mfr as coating") -> Inner clear, same mfr as coating | H16: EN
A17: 13 | B17: ECLAZ ONE II | C17: 4, 5, 6 | D17: 4/4, 5/4, 5/5, 6/4, 6/5, 6/6 | E17: 6 | F17: Using II (to-be-tempered); Commercial name: ECLAZ Zen | G17: =IF(ISNUMBER(SEARCH("Starphire",B17)),"Inner clear — Vitro Starphire (low-iron match)","Inner clear, same mfr as coating") -> Inner clear, same mfr as coating | H17: EN
A18: 14 | B18: SKN 183 II | C18: 6 | D18: 6/4, 6/5, 6/6 | E18: 3 | F18: Using II (current); 6mm only in IGSDB | G18: =IF(ISNUMBER(SEARCH("Starphire",B18)),"Inner clear — Vitro Starphire (low-iron match)","Inner clear, same mfr as coating") -> Inner clear, same mfr as coating | H18: EN
A19: 15 | B19: XTREME 61-29 II | C19: 4, 6 | D19: 4/4, 6/4, 6/5, 6/6 | E19: 4 | F19: Using II (current); no 5mm in IGSDB | G19: =IF(ISNUMBER(SEARCH("Starphire",B19)),"Inner clear — Vitro Starphire (low-iron match)","Inner clear, same mfr as coating") -> Inner clear, same mfr as coating | H19: EN
B20: Package 1 Subtotal: (8 × 6) + (2 × 5) + (2 × 3) + 6 + 4 | E20: 80
A22: Package 2 — Tinted Substrate Coatings (6mm outer only)
A23: # | B23: Coating (Surface 2) | C23: IGSDB Thicknesses | D23: Available Combos (outer/inner mm) | E23: Configs | F23: Notes | G23: Clear lite (inner)
A24: 16 | B24: SB60 Solexia | C24: 6 | D24: 6/4, 6/5, 6/6 | E24: 3 | F24: 6mm only in IGSDB | G24: =IF(ISNUMBER(SEARCH("Starphire",B24)),"Inner clear — Vitro Starphire (low-iron match)","Inner clear, same mfr as coating") -> Inner clear, same mfr as coating
A25: 17 | B25: SB60 Solarbronze | C25: 5, 6 | D25: 6/4, 6/5, 6/6 | E25: 3 | G25: =IF(ISNUMBER(SEARCH("Starphire",B25)),"Inner clear — Vitro Starphire (low-iron match)","Inner clear, same mfr as coating") -> Inner clear, same mfr as coating
A26: 18 | B26: SB60 Solargray | C26: 4, 5, 6 | D26: 6/4, 6/5, 6/6 | E26: 3 | G26: =IF(ISNUMBER(SEARCH("Starphire",B26)),"Inner clear — Vitro Starphire (low-iron match)","Inner clear, same mfr as coating") -> Inner clear, same mfr as coating
A27: 19 | B27: SB60 Optigray | C27: 6 | D27: 6/4, 6/5, 6/6 | E27: 3 | F27: 6mm only in IGSDB | G27: =IF(ISNUMBER(SEARCH("Starphire",B27)),"Inner clear — Vitro Starphire (low-iron match)","Inner clear, same mfr as coating") -> Inner clear, same mfr as coating
A28: 20 | B28: SB60 Solarblue | C28: 6 | D28: 6/4, 6/5, 6/6 | E28: 3 | F28: 6mm only in IGSDB | G28: =IF(ISNUMBER(SEARCH("Starphire",B28)),"Inner clear — Vitro Starphire (low-iron match)","Inner clear, same mfr as coating") -> Inner clear, same mfr as coating
A29: 21 | B29: SB60 Optiblue | C29: 5, 6 | D29: 6/4, 6/5, 6/6 | E29: 3 | G29: =IF(ISNUMBER(SEARCH("Starphire",B29)),"Inner clear — Vitro Starphire (low-iron match)","Inner clear, same mfr as coating") -> Inner clear, same mfr as coating
B30: Package 2 Subtotal: 6 × 3 | E30: 18
A32: ENTHERMAL TOTAL | E32: 98

Sheet Enthermal_List
A1: Product | B1: Outboard Lite Name (IGDB) | C1: Outboard IGDB ID | D1: Gap | E1: Inboard Lite Name (IGDB) | F1: Inboard IGDB ID | G1: Manufacturer
A2: Enthermal | B2: LoE 180 on 4mm Clear | C2: 2192 | D2: Vacuum 0.25mm | E2: Cardinal Clear Float Glass 4mm | F2: 2002 | G2: Cardinal Glass Industries
A3: Enthermal | B3: LoE 180 on 5mm Clear | C3: 2193 | D3: Vacuum 0.25mm | E3: Cardinal Clear Float Glass 4mm | F3: 2002 | G3: Cardinal Glass Industries
A4: Enthermal | B4: LoE 180 on 5mm Clear | C4: 2193 | D4: Vacuum 0.25mm | E4: Cardinal Clear Float Glass 5mm | F4: 2003 | G4: Cardinal Glass Industries
A5: Enthermal | B5: LoE 180 on 6mm Clear | C5: 2194 | D5: Vacuum 0.25mm | E5: Cardinal Clear Float Glass 4mm | F5: 2002 | G5: Cardinal Glass Industries
A6: Enthermal | B6: LoE 180 on 6mm Clear | C6: 2194 | D6: Vacuum 0.25mm | E6: Cardinal Clear Float Glass 5mm | F6: 2003 | G6: Cardinal Glass Industries
A7: Enthermal | B7: LoE 180 on 6mm Clear | C7: 2194 | D7: Vacuum 0.25mm | E7: Cardinal Clear Float Glass 6mm | F7: 2004 | G7: Cardinal Glass Industries
A8: Enthermal | B8: LoE² 270 on 4mm Clear | C8: 2027 | D8: Vacuum 0.25mm | E8: Cardinal Clear Float Glass 4mm | F8: 2002 | G8: Cardinal Glass Industries
A9: Enthermal | B9: LoE² 270 on 5mm Clear | C9: 2028 | D9: Vacuum 0.25mm | E9: Cardinal Clear Float Glass 4mm | F9: 2002 | G9: Cardinal Glass Industries
A10: Enthermal | B10: LoE² 270 on 5mm Clear | C10: 2028 | D10: Vacuum 0.25mm | E10: Cardinal Clear Float Glass 5mm | F10: 2003 | G10: Cardinal Glass Industries
A11: Enthermal | B11: LoE² 270 on 6mm Clear | C11: 2029 | D11: Vacuum 0.25mm | E11: Cardinal Clear Float Glass 4mm | F11: 2002 | G11: Cardinal Glass Industries
A12: Enthermal | B12: LoE² 270 on 6mm Clear | C12: 2029 | D12: Vacuum 0.25mm | E12: Cardinal Clear Float Glass 5mm | F12: 2003 | G12: Cardinal Glass Industries
A13: Enthermal | B13: LoE² 270 on 6mm Clear | C13: 2029 | D13: Vacuum 0.25mm | E13: Cardinal Clear Float Glass 6mm | F13: 2004 | G13: Cardinal Glass Industries
... A99: Enthermal | B99: Solarban® 60 on Optiblue® (Solarban® z50) 6mm | C99: 5424 | D99: Vacuum 0.25mm | E99: Vitro Clear Float Glass 6mm | F99: 415 | G99: Vitro formerly PPG

Sheet EnthermalP_Inboard_Configs
A1: Enthermal Plus Inboard — Triple Pane (Low-E on Surfaces 2 & 4, and 2 & 5) — IGSDB Verified
A3: Surface 2 Coatings (Outer Pane) — 26 options
A4: # | B4: Coating (Surface 2) | C4: Manufacturer | D4: IGSDB Thicknesses | E4: Notes
A5: 1 | B5: C180 | C5: Cardinal | D5: 4, 5, 6
A6: 2 | B6: C270 | C6: Cardinal | D6: 4, 5, 6
A7: 3 | B7: C272 | C7: Cardinal | D7: 4, 5, 6
A8: 4 | B8: C340 | C8: Cardinal | D8: 4, 5, 6
A9: 5 | B9: C366 | C9: Cardinal | D9: 4, 5, 6
A10: 6 | B10: C452 | C10: Cardinal | D10: 4, 5, 6
A11: 7 | B11: SB60 Clear | C11: Vitro | D11: 4, 5, 6
A12: 8 | B12: SB60 Solexia | C12: Vitro | D12: 6 | E12: 6mm only in IGSDB
A13: 9 | B13: SB60 Solarbronze | C13: Vitro | D13: 5, 6
A14: 10 | B14: SB60 Solargray | C14: Vitro | D14: 4, 5, 6
A15: 11 | B15: SB60 Optigray | C15: Vitro | D15: 6 | E15: 6mm only in IGSDB
A16: 12 | B16: SB60 Solarblue | C16: Vitro | D16: 6 | E16: 6mm only in IGSDB
A17: 13 | B17: SB60 Optiblue | C17: Vitro | D17: 5, 6
A18: 14 | B18: SB60 Starphire | C18: Vitro | D18: 5, 6 | E18: No 4mm in IGSDB; maps to SB60 on Starphire substrate
A19: 15 | B19: SB70 Clear | C19: Vitro | D19: 4, 5, 6
A20: 16 | B20: SB70 Solexia | C20: Vitro | D20: 6 | E20: 6mm only in IGSDB
A21: 17 | B21: SB70 Solarbronze | C21: Vitro | D21: 6 | E21: 6mm only in IGSDB
A22: 18 | B22: SB70 Solargray | C22: Vitro | D22: 5, 6 | E22: No 4mm in IGSDB
A23: 19 | B23: SB70 Optigray | C23: Vitro | D23: 6 | E23: 6mm only in IGSDB
A24: 20 | B24: SB70 Solarblue | C24: Vitro | D24: 6 | E24: 6mm only in IGSDB
A25: 21 | B25: SB70 Optiblue | C25: Vitro | D25: 5, 6 | E25: No 4mm in IGSDB
A26: 22 | B26: SB72 Starphire | C26: Vitro | D26: 6 | E26: 6mm only in IGSDB; maps to SB70 on Starphire substrate
A27: 23 | B27: ECLAZ II | C27: Saint-Gobain | D27: 4, 5, 6 | E27: Using II (to-be-tempered); Commercial name: ECLAZ Lumi
A28: 24 | B28: ECLAZ ONE II | C28: Saint-Gobain | D28: 4, 5, 6 | E28: Using II (to-be-tempered); Commercial name: ECLAZ Zen
A29: 25 | B29: SKN 183 II | C29: Saint-Gobain | D29: 6 | E29: Using II (current); 6mm only in IGSDB
A30: 26 | B30: XTREME 61-29 II | C30: Saint-Gobain | D30: 4, 6 | E30: Using II (current); no 5mm in IGSDB
A32: Surface 4 or 5 Coatings (Middle or Inner Pane) — 10 options
A33: # | B33: Coating (Surface 4 or 5) | C33: Manufacturer | D33: IGSDB Thicknesses | E33: Notes
A34: 1 | B34: C180 | C34: Cardinal | D34: 4, 5, 6
A35: 2 | B35: C270 | C35: Cardinal | D35: 4, 5, 6
A36: 3 | B36: C272 | C36: Cardinal | D36: 4, 5, 6
A37: 4 | B37: C366 | C37: Cardinal | D37: 4, 5, 6
A38: 5 | B38: SB60 Clear | C38: Vitro | D38: 4, 5, 6
A39: 6 | B39: SB70 Clear | C39: Vitro | D39: 4, 5, 6
A40: 7 | B40: ECLAZ II | C40: Saint-Gobain | D40: 4, 5, 6 | E40: Using II (current); ZEN not in IGSDB
A41: 8 | B41: SKN 183 II | C41: Saint-Gobain | D41: 6 | E41: Using II (current); 6mm only in IGSDB
A42: 9 | B42: SB60 Starphire | C42: Vitro | D42: 5, 6 | E42: No 4mm in IGSDB; maps to SB60 on Starphire substrate
...

Sheet EnthermalP_Inboard_List
A1: Product | B1: Outboard Lite Name (IGDB) | C1: Outboard IGDB ID | D1: Gap 1 | E1: Middle Lite Name (IGDB) | F1: Middle IGDB ID | G1: Gap 2 | H1: 2nd LoE Surface | I1: Inboard Lite Name (IGDB) | J1: Inboard IGDB ID | K1: Outboard Manufacturer | L1: Inboard Manufacturer | M1: Notes
A2: EnthermalPlus | B2: LoE 180 on 4mm Clear | C2: 2192 | D2: Argon 90% | E2: LoE 180 on 4mm Clear | F2: 2192 | G2: Vacuum 0.25mm | H2: Surface 4 | I2: Cardinal Clear Float Glass 4mm | J2: 2002 | K2: Cardinal Glass Industries | L2: Cardinal Glass Industries
A3: EnthermalPlus | B3: LoE 180 on 4mm Clear | C3: 2192 | D3: Argon 90% | E3: LoE² 270 on 4mm Clear | F3: 2027 | G3: Vacuum 0.25mm | H3: Surface 4 | I3: Cardinal Clear Float Glass 4mm | J3: 2002 | K3: Cardinal Glass Industries | L3: Cardinal Glass Industries
A4: EnthermalPlus | B4: LoE 180 on 4mm Clear | C4: 2192 | D4: Argon 90% | E4: LoE² 272 on 4 mm Clear | F4: 2012 | G4: Vacuum 0.25mm | H4: Surface 4 | I4: Cardinal Clear Float Glass 4mm | J4: 2002 | K4: Cardinal Glass Industries | L4: Cardinal Glass Industries
A5: EnthermalPlus | B5: LoE 180 on 4mm Clear | C5: 2192 | D5: Argon 90% | E5: LoE³ 366 on 4mm Clear | F5: 2155 | G5: Vacuum 0.25mm | H5: Surface 4 | I5: Cardinal Clear Float Glass 4mm | J5: 2002 | K5: Cardinal Glass Industries | L5: Cardinal Glass Industries
A6: EnthermalPlus | B6: LoE 180 on 4mm Clear | C6: 2192 | D6: Argon 90% | E6: Solarban® 60 on Clear 4mm | F6: 5282 | G6: Vacuum 0.25mm | H6: Surface 4 | I6: Vitro Clear Float Glass 4mm | J6: 413 | K6: Cardinal Glass Industries | L6: Vitro formerly PPG
A7: EnthermalPlus | B7: LoE 180 on 4mm Clear | C7: 2192 | D7: Argon 90% | E7: Solarban® 70 glass 4mm | F7: 5433 | G7: Vacuum 0.25mm | H7: Surface 4 | I7: Vitro Clear Float Glass 4mm | J7: 413 | K7: Cardinal Glass Industries | L7: Vitro formerly PPG
A8: EnthermalPlus | B8: LoE 180 on 4mm Clear | C8: 2192 | D8: Argon 90% | E8: SGG ECLAZ II 4mm | F8: 20754 | G8: Vacuum 0.25mm | H8: Surface 4 | I8: SGG PLANICLEAR 4mm | J8: 21011 | K8: Cardinal Glass Industries | L8: Saint-Gobain Glass
A9: EnthermalPlus | B9: LoE² 270 on 4mm Clear | C9: 2027 | D9: Argon 90% | E9: LoE 180 on 4mm Clear | F9: 2192 | G9: Vacuum 0.25mm | H9: Surface 4 | I9: Cardinal Clear Float Glass 4mm | J9: 2002 | K9: Cardinal Glass Industries | L9: Cardinal Glass Industries
A10: EnthermalPlus | B10: LoE² 270 on 4mm Clear | C10: 2027 | D10: Argon 90% | E10: LoE² 270 on 4mm Clear | F10: 2027 | G10: Vacuum 0.25mm | H10: Surface 4 | I10: Cardinal Clear Float Glass 4mm | J10: 2002 | K10: Cardinal Glass Industries | L10: Cardinal Glass Industries
A11: EnthermalPlus | B11: LoE² 270 on 4mm Clear | C11: 2027 | D11: Argon 90% | E11: LoE² 272 on 4 mm Clear | F11: 2012 | G11: Vacuum 0.25mm | H11: Surface 4 | I11: Cardinal Clear Float Glass 4mm | J11: 2002 | K11: Cardinal Glass Industries | L11: Cardinal Glass Industries
A12: EnthermalPlus | B12: LoE² 270 on 4mm Clear | C12: 2027 | D12: Argon 90% | E12: LoE³ 366 on 4mm Clear | F12: 2155 | G12: Vacuum 0.25mm | H12: Surface 4 | I12: Cardinal Clear Float Glass 4mm | J12: 2002 | K12: Cardinal Glass Industries | L12: Cardinal Glass Industries
A13: EnthermalPlus | B13: LoE² 270 on 4mm Clear | C13: 2027 | D13: Argon 90% | E13: Solarban® 60 on Clear 4mm | F13: 5282 | G13: Vacuum 0.25mm | H13: Surface 4 | I13: Vitro Clear Float Glass 4mm | J13: 413 | K13: Cardinal Glass Industries | L13: Vitro formerly PPG
... A4471: EnthermalPlus | B4471: Solarban® 72 on Starphire® 6mm | C4471: 5435 | D4471: Air 100% | E4471: Vitro Starphire 6mm | F4471: 5004 | G4471: Vacuum 0.25mm | H4471: Surface 5 | I4471: Solarban® 72 on Starphire® 6mm | J4471: 5435 | K4471: Vitro formerly PPG | L4471: Vitro formerly PPG

Sheet EnthermalP_Outboard
A1: Enthermal Plus Outboard — Triple Pane (Low-E on Surfaces 2 & 5) — IGSDB Verified
A3: Surface 2 Coatings (Outer Pane) — 21 options
A4: # | B4: Coating (Surface 2) | C4: IGSDB Thicknesses | D4: Notes
A5: 1 | B5: C180 | C5: 4, 5, 6
A6: 2 | B6: C270 | C6: 4, 5, 6
A7: 3 | B7: C272 | C7: 4, 5, 6
A8: 4 | B8: C340 | C8: 4, 5, 6
A9: 5 | B9: C366 | C9: 4, 5, 6
A10: 6 | B10: C452 | C10: 4, 5, 6
A11: 7 | B11: SB60 Clear | C11: 4, 5, 6
A12: 8 | B12: SB70 Clear | C12: 4, 5, 6
A13: 9 | B13: SB67 | C13: 5, 6 | D13: No 4mm in IGSDB
A14: 10 | B14: SB60 Starphire | C14: 5, 6 | D14: No 4mm in IGSDB; maps to SB60 on Starphire substrate
A15: 11 | B15: SB72 Starphire | C15: 6 | D15: 6mm only in IGSDB; maps to SB70 on Starphire substrate
A16: 12 | B16: ECLAZ II | C16: 4, 5, 6 | D16: Using II (to-be-tempered); Commercial name: ECLAZ Lumi
A17: 13 | B17: ECLAZ ONE II | C17: 4, 5, 6 | D17: Using II (to-be-tempered); Commercial name: ECLAZ Zen
A18: 14 | B18: SKN 183 II | C18: 6 | D18: Using II (current); 6mm only in IGSDB
A19: 15 | B19: XTREME 61-29 II | C19: 4, 6 | D19: Using II (current); no 5mm in IGSDB
A20: 16 | B20: SB60 Solexia | C20: 6 | D20: 6mm only in IGSDB
A21: 17 | B21: SB60 Solarbronze | C21: 5, 6
A22: 18 | B22: SB60 Solargray | C22: 4, 5, 6
A23: 19 | B23: SB60 Optigray | C23: 6 | D23: 6mm only in IGSDB
A24: 20 | B24: SB60 Solarblue | C24: 6 | D24: 6mm only in IGSDB
A25: 21 | B25: SB60 Optiblue | C25: 5, 6
A27: Surface 5 Coatings (Inner Pane) — 10 options
A28: # | B28: Coating (Surface 5) | C28: IGSDB Thicknesses | D28: Notes
A29: 1 | B29: C180 | C29: 4, 5, 6
A30: 2 | B30: C270 | C30: 4, 5, 6
A31: 3 | B31: C272 | C31: 4, 5, 6
A32: 4 | B32: C366 | C32: 4, 5, 6
A33: 5 | B33: SB60 Clear | C33: 4, 5, 6
A34: 6 | B34: SB70 Clear | C34: 4, 5, 6
A35: 7 | B35: ECLAZ II | C35: 4, 5, 6 | D35: Using II (current); ZEN not in IGSDB
A36: 8 | B36: SKN 183 II | C36: 6 | D36: Using II (current); 6mm only in IGSDB
A37: 9 | B37: SB60 Starphire | C37: 5, 6 | D37: No 4mm in IGSDB; maps to SB60 on Starphire substrate
A38: 10 | B38: SB72 Starphire | C38: 6 | D38: 6mm only in IGSDB; maps to SB70 on Starphire substrate
A40: S2 Coatings Available by Outer Pane Thickness
A41: Outer Thickness | B41: S2 Count | C41: Not Available in IGSDB | H41: Starphire-Constrained Counts (SP pairs only with SP)
A42: 4mm | B42: 12 | C42: SB67, SB60 Starphire, SB72 Starphire, SKN 183 II, Solexia, Solarbronze, Optigray, Solarblue, Optiblue | H42: Thickness | I42: S2 non-SP | J42: S2 SP | K42: S5 non-SP | L42: S5 SP
A43: 5mm | B43: 15 | C43: SB72 Starphire, SKN 183 II, XTREME 61-29 II, Solexia, Optigray, Solarblue | H43: 4mm | I43: 12 | J43: 0 | K43: 7 | L43: 0
...

Sheet EnthermalP_Outboard_List
A1: Product | B1: Outboard Lite Name (IGDB) | C1: Outboard IGDB ID | D1: Gap 1 | E1: Middle Lite Name (IGDB) | F1: Middle IGDB ID | G1: Gap 2 | H1: 2nd LoE Surface | I1: Inboard Lite Name (IGDB) | J1: Inboard IGDB ID | K1: Outboard Manufacturer | L1: Inboard Manufacturer | M1: Notes
A2: EnthermalPlus | B2: LoE 180 on 4mm Clear | C2: 2192 | D2: Vacuum 0.25mm | E2: Cardinal Clear Float Glass 4mm | F2: 2002 | G2: Argon 90% | H2: Surface 5 | I2: LoE 180 on 4mm Clear | J2: 2192 | K2: Cardinal Glass Industries | L2: Cardinal Glass Industries
A3: EnthermalPlus | B3: LoE 180 on 4mm Clear | C3: 2192 | D3: Vacuum 0.25mm | E3: Cardinal Clear Float Glass 4mm | F3: 2002 | G3: Argon 90% | H3: Surface 5 | I3: LoE² 270 on 4mm Clear | J3: 2027 | K3: Cardinal Glass Industries | L3: Cardinal Glass Industries
A4: EnthermalPlus | B4: LoE 180 on 4mm Clear | C4: 2192 | D4: Vacuum 0.25mm | E4: Cardinal Clear Float Glass 4mm | F4: 2002 | G4: Argon 90% | H4: Surface 5 | I4: LoE² 272 on 4 mm Clear | J4: 2012 | K4: Cardinal Glass Industries | L4: Cardinal Glass Industries
A5: EnthermalPlus | B5: LoE 180 on 4mm Clear | C5: 2192 | D5: Vacuum 0.25mm | E5: Cardinal Clear Float Glass 4mm | F5: 2002 | G5: Argon 90% | H5: Surface 5 | I5: LoE³ 366 on 4mm Clear | J5: 2155 | K5: Cardinal Glass Industries | L5: Cardinal Glass Industries
A6: EnthermalPlus | B6: LoE 180 on 4mm Clear | C6: 2192 | D6: Vacuum 0.25mm | E6: Cardinal Clear Float Glass 4mm | F6: 2002 | G6: Argon 90% | H6: Surface 5 | I6: Solarban® 60 on Clear 4mm | J6: 5282 | K6: Cardinal Glass Industries | L6: Vitro formerly PPG
A7: EnthermalPlus | B7: LoE 180 on 4mm Clear | C7: 2192 | D7: Vacuum 0.25mm | E7: Cardinal Clear Float Glass 4mm | F7: 2002 | G7: Argon 90% | H7: Surface 5 | I7: Solarban® 70 glass 4mm | J7: 5433 | K7: Cardinal Glass Industries | L7: Vitro formerly PPG
A8: EnthermalPlus | B8: LoE 180 on 4mm Clear | C8: 2192 | D8: Vacuum 0.25mm | E8: Cardinal Clear Float Glass 4mm | F8: 2002 | G8: Argon 90% | H8: Surface 5 | I8: SGG ECLAZ II 4mm | J8: 20754 | K8: Cardinal Glass Industries | L8: Saint-Gobain Glass
A9: EnthermalPlus | B9: LoE² 270 on 4mm Clear | C9: 2027 | D9: Vacuum 0.25mm | E9: Cardinal Clear Float Glass 4mm | F9: 2002 | G9: Argon 90% | H9: Surface 5 | I9: LoE 180 on 4mm Clear | J9: 2192 | K9: Cardinal Glass Industries | L9: Cardinal Glass Industries
A10: EnthermalPlus | B10: LoE² 270 on 4mm Clear | C10: 2027 | D10: Vacuum 0.25mm | E10: Cardinal Clear Float Glass 4mm | F10: 2002 | G10: Argon 90% | H10: Surface 5 | I10: LoE² 270 on 4mm Clear | J10: 2027 | K10: Cardinal Glass Industries | L10: Cardinal Glass Industries
A11: EnthermalPlus | B11: LoE² 270 on 4mm Clear | C11: 2027 | D11: Vacuum 0.25mm | E11: Cardinal Clear Float Glass 4mm | F11: 2002 | G11: Argon 90% | H11: Surface 5 | I11: LoE² 272 on 4 mm Clear | J11: 2012 | K11: Cardinal Glass Industries | L11: Cardinal Glass Industries
A12: EnthermalPlus | B12: LoE² 270 on 4mm Clear | C12: 2027 | D12: Vacuum 0.25mm | E12: Cardinal Clear Float Glass 4mm | F12: 2002 | G12: Argon 90% | H12: Surface 5 | I12: LoE³ 366 on 4mm Clear | J12: 2155 | K12: Cardinal Glass Industries | L12: Cardinal Glass Industries
A13: EnthermalPlus | B13: LoE² 270 on 4mm Clear | C13: 2027 | D13: Vacuum 0.25mm | E13: Cardinal Clear Float Glass 4mm | F13: 2002 | G13: Argon 90% | H13: Surface 5 | I13: Solarban® 60 on Clear 4mm | J13: 5282 | K13: Cardinal Glass Industries | L13: Vitro formerly PPG
... A1877: EnthermalPlus | B1877: Solarban® 72 on Starphire® 6mm | C1877: 5435 | D1877: Vacuum 0.25mm | E1877: Vitro Starphire 6mm | F1877: 5004 | G1877: Air 100% | H1877: Surface 5 | I1877: Solarban® 72 on Starphire® 6mm | J1877: 5435 | K1877: Vitro formerly PPG | L1877: Vitro formerly PPG

Sheet Configs_Summary
A1: VIG Product Options — Grand Summary
A3: Product Line | B3: Type | C3: Low-E Surfaces | D3: S2 Coatings | E3: S4/S5 Coatings | F3: Thickness Combos | G3: Gas Options | H3: Coating Pairs | I3: Total Configs
A4: Enthermal | B4: Double Pane | C4: 2 | D4: 21 (Pkg1: 15, Pkg2: 6) | E4: N/A | F4: 6 + 3 | G4: N/A | H4: 98 | I4: 98
A5: Enthermal Plus Outboard | B5: Triple Pane | C5: 2 & 5 | D5: 21 | E5: 10 | F5: 8 | G5: 2 (Air, Ar90) | H5: =EnthermalP_Outboard!F62 -> 938 | I5: =EnthermalP_Outboard!F64 -> 1876
A6: Enthermal Plus Inboard (S2&4) | B6: Triple Pane | C6: 2 & 4 | D6: 26 | E6: 10 | F6: 8 | G6: 2 (Air, Ar90) | H6: =EnthermalP_Inboard_Configs!F67 -> 1131 | I6: =EnthermalP_Inboard_Configs!F67*2 -> 2262
A7: Enthermal Plus Inboard (S2&5) | B7: Triple Pane | C7: 2 & 5 | D7: 26 | E7: 10 | F7: 8 | G7: 2 (Air, Ar90) | H7: =EnthermalP_Inboard_Configs!F79 -> 1104 | I7: =EnthermalP_Inboard_Configs!F79*2 -> 2208
A8: GRAND TOTAL | I8: =SUM(I4:I7) -> 6444
A10: Coating Inventory by Manufacturer
A11: Manufacturer | B11: S2 Coatings (Enthermal & Outboard) | C11: S2 Coatings (Inboard adds) | D11: S4/S5 Coatings | E11: Total Unique
A12: Cardinal | B12: C180, C270, C272, C340, C366, C452 | C12: — (same 6) | D12: C180, C270, C272, C366 | E12: 6
A13: Vitro | B13: SB60 Clear, SB70 Clear, SB67, SB60 Starphire, SB72 Starphire, SB60 Solexia/Solarbronze/Solargray/Optigray/Solarblue/Optiblue | C13: SB70 Solexia/Solarbronze/Solargray/Optigray/Solarblue/Optiblue (SB67 removed) | D13: SB60 Clear, SB70 Clear, SB60 Starphire, SB72 Starphire | E13: 17
A14: Saint-Gobain | B14: ECLAZ II, ECLAZ ONE II, SKN 183 II, XTREME 61-29 II | C14: — (same 4) | D14: ECLAZ II, SKN 183 II | E14: 4
A15: Total unique coatings | E15: 27
A17: Thickness Combinations
A18: Product Line | B18: Combos (outer/mid or inner, mm) | C18: Count
A19: Enthermal (Pkg 1) | B19: 4/4, 5/4, 5/5, 6/4, 6/5, 6/6 | C19: 6
A20: Enthermal (Pkg 2) | B20: 6/4, 6/5, 6/6 | C20: 3
A21: Enthermal Plus (all) | B21: 4/4/4, 5/4/4, 6/4/4, 5/5/4, 5/5/5, 6/5/5, 6/6/5, 6/6/6 | C21: 8
A23: Key IGSDB Availability Constraints
A24: Coating | B24: Available Thicknesses | C24: Impact
A25: SB67 | B25: 5, 6mm only | C25: Excluded from 4mm outer combos (Enthermal & Outboard only)
A26: SKN 183 II | B26: 6mm only | C26: Limited to 6mm outer and 6mm S4/S5 combos
A27: XTREME 61-29 II | B27: 4, 6mm only | C27: Excluded from 5mm outer combos
A28: SB60 Solexia | B28: 6mm only | C28: Limited to 6mm outer combos
A29: SB60 Optigray | B29: 6mm only | C29: Limited to 6mm outer combos
A30: SB60 Solarblue | B30: 6mm only | C30: Limited to 6mm outer combos
A31: SB70 Solexia | B31: 6mm only | C31: Limited to 6mm outer combos (Inboard only)
A32: SB70 Solarbronze | B32: 6mm only | C32: Limited to 6mm outer combos (Inboard only)
A33: SB70 Optigray | B33: 6mm only | C33: Limited to 6mm outer combos (Inboard only)
A34: SB70 Solarblue | B34: 6mm only | C34: Limited to 6mm outer combos (Inboard only)
A35: SB60 Starphire | B35: 5, 6mm only | C35: Excluded from 4mm outer combos
A36: SB72 Starphire | B36: 6mm only | C36: Limited to 6mm outer combos
A38: Notes:
A39: • Enthermal has no gas fill option (vacuum gap only).
A40: • Enthermal Plus has 2 gas fill options (Air, Argon 90%) for the air gap.
A41: • Air gap thickness adjusted to maintain 25.4 mm (1 inch) total thickness.
A42: • Cross-manufacturer coating combinations are allowed, EXCEPT Starphire (low-iron): Starphire coatings pair only with Starphire, so all panes are low-iron (Vitro Starphire clear).
A43: • Saint-Gobain products use II (current production) variant in IGSDB.
A44: • SB67 appears only in Enthermal and Outboard S2 lists; SB70 tinted variants appear only in Inboard S2 list. Starphire products appear in all S2 lists and in the S4/S5 inner lists.
A45: • ECLAZ II = ECLAZ Lumi; ECLAZ ONE II = ECLAZ Zen (Saint-Gobain ECLAZ range, Oct 2023).

Sheet Skill_Instructions
A1: SKILL: Enthermal List Builder (Dynamic)
A2: Purpose: Dynamically generate the Enthermal_List table from whatever coatings and combos exist in Enthermal Configs. Handles any number of coatings, packages, and combinations.
A4: PREREQUISITES
A5: Required Sheet | B5: Description | C5: Key Columns
A6: Enthermal Configs | B6: 21 coatings (Pkg1: 15 clear, Pkg2: 6 tinted) + available thickness combos | C6: Col D = Available Combos (outer_mm/inner_mm)
A7: IGSDB Product Availability | B7: Maps coating + thickness (4/5/6mm) → IGSDB ID number | C7: Cols C/D/E = IDs for 4mm/5mm/6mm
A8: IGSDB_110 | B8: Full IGSDB database (6,590 rows) — exact product names | C8: Col A = ID, Col S = ProductName, Col R = Manufacturer
A9: CreateList_Rules | B9: Column schema and business rules for the output table | C9: Defines columns A–G + H (Notes, optional)
A10: Enthermal_List | B10: Target output sheet — headers in row 1, data starts row 2 | C10: Cols A–G (Product thru Manufacturer)
A12: OUTPUT SCHEMA
A13: Column | B13: Header | C13: Rule
A14: A | B14: Product | C14: Always "Enthermal"
A15: B | B15: Outboard Lite Name (IGDB) | C15: Product name per list convention — human-readable commercial name + thickness (e.g. 'LoE 180 on 4mm Clear', 'Solarban® 60 on Starphire® 5mm'), looked up by IGDB ID. NOT the raw IGSDB_110 col S coded name.
A16: C | B16: Outboard IGDB ID | C16: Numeric ID from IGSDB Product Availability (coating + outer thickness)
A17: D | B17: Gap | C17: Always "Vacuum 0.25mm"
A18: E | B18: Inboard Lite Name (IGDB) | C18: Clear-lite name per list convention — manufacturer + product + thickness (e.g. 'Vitro Starphire 4mm', 'Cardinal Clear Float Glass 4mm', 'SGG PLANICLEAR 4mm'). NOT the raw IGSDB_110 col S coded name.
A19: F | B19: Inboard IGDB ID | C19: Numeric ID from IGSDB Product Availability (same mfg's clear float + inner thickness)
A20: G | B20: Manufacturer | C20: Manufacturer of ALL lites — must be same for outboard and inboard
A22: BUSINESS RULES
A23: Rule # | B23: Rule | C23: Detail
A24: 1 | B24: Thickness constraint | C24: Outboard thickness must be ≥ inboard thickness. 5/4 = valid. 4/5 = NOT valid.
A25: 2 | B25: Same manufacturer | C25: Cardinal coatings → Cardinal clear (2002/2003/2004). Vitro coatings → Vitro clear (413/414/415). Saint-Gobain → SGG PLANICLEAR (21011/21012/21013). EXCEPTION — substrate match: coatings on a Starphire (low-iron) substrate (SB60 Starphire, SB72 Starphire) must pair with Vitro Starphire clear (5002=4mm / 5003=5mm / 5004=6mm), NOT standard Vitro clear float.
A26: 3 | B26: Product naming convention | C26: Cols B and E follow the human-readable naming convention used in the list (commercial/manufacturer name + thickness), NOT raw IGSDB_110 col S coded names. E.g. 'Vitro Starphire 4mm', 'Cardinal Clear Float Glass 4mm', 'SGG PLANICLEAR 4mm'.
A28: WORKFLOW (4 STEPS)
A29: Step 1: Read Reference Data
A30: 1a | B30: Read IGSDB Product Availability (full used range) | C30: Build coating-to-ID mapping dynamically. Each row = one coating, cols C/D/E = IDs per thickness. Also capture all clear float glass rows (at bottom, identified by name containing "Clear" or "Float" or "PLANICLEAR"). Note each coating's manufacturer.
A31: 1b | B31: Read Enthermal Configs (full used range) | C31: Scan all rows dynamically. Detect package headers (col A starts with "Package"). Detect coating rows (col A is numeric). For each coating row: read col B (coating name), col C (available thicknesses), col D (available combos as outer/inner pairs). Stop at TOTAL row. Do NOT hardcode row numbers — the sheet may have more or fewer coatings.
A32: 1c | B32: Search IGSDB_110 in chunks of 1000 rows | C32: Collect ALL unique IGDB IDs from steps 1a (coated + clear). Read col A (ID) and col S (ProductName, index 18) and col R (Manufacturer, index 17). Build a lookup map: ID → {ProductName, Manufacturer}. The sheet may grow beyond 6,590 rows — always read to the actual used range.
A34: Step 2: Build All Rows (Dynamic Count)
B35: For each coating found in Enthermal Configs (in row order):
B36: For each combo (outer_mm / inner_mm):
B37: 1. Lookup outboard IGDB ID (coating + outer_mm) | C37: From IGSDB Product Availability
B38: 2. Lookup outboard ProductName (by ID) | C38: From IGSDB_110 col S
B39: 3. Lookup inboard clear float ID (same mfg + inner_mm) | C39: From IGSDB Product Availability
B40: 4. Lookup inboard ProductName (by ID) | C40: From IGSDB_110 col S
B41: 5. Validate outer_mm ≥ inner_mm, write row | C41: ["Enthermal", outboard_name, outboard_id, "Vacuum 0.25mm", inboard_name, inboard_id, manufacturer]
B42: Total row count = sum of all combos across all coatings. Verify against TOTAL cell in Enthermal Configs (col E).
A43: Step 3: Clear & Write to Enthermal_List
A44: 3a | B44: Clear ALL existing data below header row 1 (A2:G to last used row) | C44: Do not assume 84 rows — clear the entire used range below headers.
A45: 3b | B45: Write rows in batches (≤42 per batch via execute_office_js)
...

Sheet Audit Rules
A1: ENTHERMAL GLASS CONFIGURATION — AUDIT RULES
A3: SHEET STRUCTURE
A4: Sheet Name | B4: Type | C4: Columns
A5: Enthermal_List | B5: Dual-pane VIG (coated + clear) | C5: A–G: Product, Outboard Lite Name, Outboard IGDB ID, Gap, Inboard Lite Name, Inboard IGDB ID, Manufacturer
A6: EnthermalP_Inboard_List | B6: Triple-pane, VIG on inboard side | C6: A–N: Product, Outboard Lite Name, Outboard IGDB ID, Gap 1, Middle Lite Name, Middle IGDB ID, Gap 2, 2nd LoE Surface, Inboard Lite Name, Inboard IGDB ID, Outboard Mfr, Inboard Mfr, Notes, New Addition
A7: EnthermalP_Outboard_List | B7: Triple-pane, VIG on outboard side | C7: Same 14-column schema as Inboard list (A–N, incl. New Addition)
A9: VALIDATION CHECKS — APPLY TO EVERY DATA ROW
A10: # | B10: Rule | C10: Details
A11: 1 | B11: ID existence | C11: Every IGDB ID in cols C, F, and J (where applicable) must exist in the IGSDB_110 sheet column A. Any unknown ID is a hard failure.
A12: 2 | B12: ID ↔ name match | C12: The product name in cols B, E, and I must exactly match the ProductName (col S) for that ID in IGSDB_110. Character-level match including superscripts (² ³) and registered marks (®).
A13: 3 | B13: Gap placement | C13: Enthermal_List: col D = "Vacuum 0.25mm" always. Inboard lists: col D (Gap 1) = gas fill, col G (Gap 2) = "Vacuum 0.25mm". Outboard lists: col D (Gap 1) = "Vacuum 0.25mm", col G (Gap 2) = gas fill. Gas fill values are "Argon 90%" or "Air 100%".
A14: 4 | B14: Gas fill sections | C14: For triple-pane lists: the first half of data rows = Argon 90%, the second half = Air 100%. The Air rows must be an exact mirror of the Argon rows with only the gas value changed (same coating pairs, same order, same surfaces). Split point is dynamic — count total data rows and divide by 2.
A15: 5 | B15: VIG same-manufacturer rule | C15: The coated lite and clear lite forming the VIG pair must share the same manufacturer (from IGSDB_110 col R). Enthermal_List: outboard (coated) + inboard (clear). Inboard Type A (Surface 4): middle (S4 coated) + inboard (clear). Inboard Type B (Surface 5): middle (clear) + inboard (S5 coated). Outboard: outboard (S2 coated) + middle (clear). The non-VIG lite (outer on Inboard, inner on Outboard) can be ANY manufacturer.
A16: 6 | B16: Coated vs clear placement | C16: Clear float IDs: Cardinal (2002, 2003, 2004), Vitro (413, 414, 415), Saint-Gobain (21011, 21012, 21013), Vitro Starphire low-iron (5002, 5003, 5004). All other IDs are coated glass. Enthermal_List: outboard=coated, inboard=clear. Inboard Type A: out=coated, mid=coated, in=clear. Inboard Type B: out=coated, mid=clear, in=coated. Outboard: out=coated, mid=clear, in=coated.
A17: 7 | B17: Surface designation | C17: Col H (2nd LoE Surface). Inboard list: "Surface 4" for Type A (S4 coated middle + clear inner), "Surface 5" for Type B (clear middle + S5 coated inner). All Type A rows come before Type B within each gas section. Outboard list: always "Surface 5". Enthermal_List has no surface column.
A18: 8 | B18: Manufacturer columns (K, L) | C18: Col K (Outboard Mfr) = mfr of the outboard coated lite. Col L (Inboard Mfr) = mfr of the inboard lite's IGDB ID: for Inboard lists this equals the VIG coated lite (S4 for Type A, S5 for Type B); for the Outboard list it is the S5 inner lite, which is NOT the VIG pair (the Outboard VIG is outer+middle). Display names: Cardinal → "Cardinal Glass Industries", Vitro → "Vitro formerly PPG", Saint-Gobain → "Saint-Gobain Glass".
A19: 9 | B19: No duplicates | C19: Within each gas section, no two rows should share the same tuple of (Outboard ID, Middle ID, 2nd LoE Surface, Inboard ID). For Enthermal_List, the tuple is (Outboard ID, Inboard ID).
A20: 10 | B20: Expected row counts | C20: Counts derive from IGSDB Product Availability and the EnthermalP_Inboard_Configs / EnthermalP_Outboard sheets. Verify by recomputing per thickness combo WITH the Starphire split: (non-Starphire S2 × non-Starphire S4/S5) + (Starphire S2 × Starphire S4/S5). Starphire pairs ONLY with Starphire, so cross terms are invalid. Sum across all combos, then × 2 for the Air duplicate. Enthermal_List = sum of (coatings at outer_mm × clear thicknesses ≤ outer_mm) per mfr. Current totals: Enthermal 98, Inboard 4,470, Outboard 1,876.
A21: 11 | B21: Starphire substrate match | C21: Starphire (low-iron) coatings pair ONLY with Starphire. If any pane is Starphire, ALL panes must be low-iron: coated = SB60/SB72 Starphire (5348/5349/5435), clear = Vitro Starphire (5002/5003/5004). A row mixing a Starphire coating with a standard coating or standard clear lite is a hard failure.
A23: REFERENCE DATA
A24: Lookup source | B24: Description
A25: IGSDB_110 | B25: Master product database. Col A = ID, Col R = Manufacturer, Col S = ProductName. Use this as the single source of truth for ID↔name and ID↔manufacturer lookups.
A26: IGSDB Product Availability | B26: Maps coating short names to IGDB IDs by thickness (4mm, 5mm, 6mm). Also lists clear float glass IDs per manufacturer. Use to verify which IDs are valid at which thicknesses.
A27: EnthermalP_Inboard_Configs | B27: Configuration matrix showing S2 coating counts, S4/S5 coating counts, and thickness combos for Inboard list. Use to derive expected row counts per thickness combo.
A28: EnthermalP_Outboard | B28: Same as above but for Outboard list. Different structure: S2 + clear on outboard VIG, S5 on inboard.
A30: CONFIGURATION TYPES
A31: Config | B31: Pane layout (outside → inside) | C31: VIG pair
A32: Enthermal (dual) | B32: S2-coated lite | Vacuum 0.25mm | Clear float | C32: Both lites = same manufacturer
A33: Inboard Type A | B33: S2-coated (any mfr) | Gas fill | S4-coated (VIG mfr) | Vacuum 0.25mm | Clear float (VIG mfr) | C33: Middle (S4) + Inboard (clear) = same mfr
A34: Inboard Type B | B34: S2-coated (any mfr) | Gas fill | Clear float (VIG mfr) | Vacuum 0.25mm | S5-coated (VIG mfr) | C34: Middle (clear) + Inboard (S5) = same mfr
A35: Outboard | B35: S2-coated (VIG mfr) | Vacuum 0.25mm | Clear float (VIG mfr) | Gas fill | S5-coated (any mfr) | C35: Outboard (S2) + Middle (clear) = same mfr
